[2022-05-19 03:08:08,183] {taskinstance.py:1159} INFO - Dependencies all met for <TaskInstance: user_behaviour.pull_tracks_save_df scheduled__2021-05-23T00:00:00+00:00 [queued]>
[2022-05-19 03:08:08,194] {taskinstance.py:1159} INFO - Dependencies all met for <TaskInstance: user_behaviour.pull_tracks_save_df scheduled__2021-05-23T00:00:00+00:00 [queued]>
[2022-05-19 03:08:08,194] {taskinstance.py:1356} INFO - 
--------------------------------------------------------------------------------
[2022-05-19 03:08:08,195] {taskinstance.py:1357} INFO - Starting attempt 2 of 3
[2022-05-19 03:08:08,195] {taskinstance.py:1358} INFO - 
--------------------------------------------------------------------------------
[2022-05-19 03:08:08,210] {taskinstance.py:1377} INFO - Executing <Task(PythonOperator): pull_tracks_save_df> on 2021-05-23 00:00:00+00:00
[2022-05-19 03:08:08,215] {standard_task_runner.py:52} INFO - Started process 316 to run task
[2022-05-19 03:08:08,217] {standard_task_runner.py:79} INFO - Running: ['***', 'tasks', 'run', 'user_behaviour', 'pull_tracks_save_df', 'scheduled__2021-05-23T00:00:00+00:00', '--job-id', '8', '--raw', '--subdir', 'DAGS_FOLDER/demo_dag.py', '--cfg-path', '/tmp/tmp3co9kmou', '--error-file', '/tmp/tmp4big8oca']
[2022-05-19 03:08:08,219] {standard_task_runner.py:80} INFO - Job 8: Subtask pull_tracks_save_df
[2022-05-19 03:08:08,232] {logging_mixin.py:115} WARNING - /home/***/.local/lib/python3.7/site-packages/***/configuration.py:470 DeprecationWarning: The sql_alchemy_conn option in [core] has been moved to the sql_alchemy_conn option in [database] - the old setting has been used, but please update your config.
[2022-05-19 03:08:08,273] {task_command.py:369} INFO - Running <TaskInstance: user_behaviour.pull_tracks_save_df scheduled__2021-05-23T00:00:00+00:00 [running]> on host 50f383a1ddd9
[2022-05-19 03:08:08,387] {taskinstance.py:1571} INFO - Exporting the following env vars:
AIRFLOW_CTX_DAG_EMAIL=***@***.com
AIRFLOW_CTX_DAG_OWNER=***
AIRFLOW_CTX_DAG_ID=user_behaviour
AIRFLOW_CTX_TASK_ID=pull_tracks_save_df
AIRFLOW_CTX_EXECUTION_DATE=2021-05-23T00:00:00+00:00
AIRFLOW_CTX_TRY_NUMBER=2
AIRFLOW_CTX_DAG_RUN_ID=scheduled__2021-05-23T00:00:00+00:00
[2022-05-19 03:08:08,388] {taskinstance.py:1889} ERROR - Task failed with exception
Traceback (most recent call last):
  File "/home/airflow/.local/lib/python3.7/site-packages/airflow/operators/python.py", line 171, in execute
    return_value = self.execute_callable()
  File "/home/airflow/.local/lib/python3.7/site-packages/airflow/operators/python.py", line 189, in execute_callable
    return self.python_callable(*self.op_args, **self.op_kwargs)
  File "/opt/airflow/dags/pipeline.py", line 33, in top_tracks_to_df
    auth = Authenticator('user-library-read')
  File "/opt/airflow/dags/pipeline.py", line 11, in __init__
    with open("credentials/credentials.yml", "r") as stream:
FileNotFoundError: [Errno 2] No such file or directory: 'credentials/credentials.yml'
[2022-05-19 03:08:08,398] {taskinstance.py:1400} INFO - Marking task as UP_FOR_RETRY. dag_id=user_behaviour, task_id=pull_tracks_save_df, execution_date=20210523T000000, start_date=20220519T030808, end_date=20220519T030808
[2022-05-19 03:08:08,441] {standard_task_runner.py:97} ERROR - Failed to execute job 8 for task pull_tracks_save_df ([Errno 2] No such file or directory: 'credentials/credentials.yml'; 316)
[2022-05-19 03:08:08,472] {local_task_job.py:156} INFO - Task exited with return code 1
[2022-05-19 03:08:08,510] {local_task_job.py:273} INFO - 0 downstream tasks scheduled from follow-on schedule check
